Workbook

Sheet customer_master
A1: ABC Finance | Customer Master | May 2026
A2: Customer_ID | B2: Customer_Name | C2: Date_of_Birth | D2: Age | E2: Gender | F2: Mobile | G2: Alternate_Mobile | H2: Address | I2: City | J2: CIBIL_Score | K2: PIN_Code | L2: Aadhaar_Number | M2: PAN_Number | N2: KYC_Status | O2: Occupation_Type | P2: Monthly_Income | Q2: Vehicle_Make | R2: Vehicle_Model | S2: Vehicle_Type | T2: Registration_Number | U2: Vehicle_Cost | V2: Branch_Code | W2: Branch_Name | X2: RM_Name | Y2: Amount_Disbursed | Z2: Tenure_Months | AA2: Interest_Rate_% | AB2: EMI_Amount | AC2: Disbursement_Date | AD2: Maturity_Date | AE2: Repayment_Mode
A3: CUST0001 | B3: Vijay Mishra | C3: 29669 | D3: =DATEDIF(Table1[[#This Row],[Date_of_Birth]],TODAY(),"Y") -> 45 | E3: Male | F3: 9210053353 | G3: 9685582861 | H3: 433, MG Road, Indore | I3: Indore | J3: 673 | K3: 452001 | L3: XXXX-XXXX-9290 | M3: GPOSS7873H | N3: Pending | O3: Business | P3: 35000 | Q3: Bajaj | R3: Pulsar | S3: Two-Wheeler | T3: UP99GF5552 | U3: 70851 | V3: BR001 | W3: Indore | X3: Amit Sharma | Y3: 54982 | Z3: 36 | AA3: 14.31 | AB3: =-PMT((Table1[[#This Row],[Interest_Rate_%]]/100)/12,Table1[[#This Row],[Tenure_Months]],Table1[[#This Row],[Amount_Disbursed]]) -> 1887.4434 | AC3: 45674 | AD3: =EDATE(Table1[[#This Row],[Disbursement_Date]],Table1[[#This Row],[Tenure_Months]]) -> 46769 | AE3: NACH
A4: CUST0003 | B4: Mamta Dwivedi | C4: 28926 | D4: =DATEDIF(Table1[[#This Row],[Date_of_Birth]],TODAY(),"Y") -> 47 | E4: Female | F4: 9918739736 | H4: 614, Adhartal, Jabalpur | I4: Jabalpur | J4: 682 | K4: 482004 | L4: XXXX-XXXX-6258 | M4: YWVHB2290C | N4: Pending | O4: Salaried | P4: 25000 | Q4: Maruti | R4: Brezza | S4: SUV | T4: RJ80CE9645 | U4: 1136474 | V4: BR003 | W4: Jabalpur | X4: Vikas Singh | Y4: 858828 | Z4: 36 | AA4: 11.79 | AB4: =-PMT((Table1[[#This Row],[Interest_Rate_%]]/100)/12,Table1[[#This Row],[Tenure_Months]],Table1[[#This Row],[Amount_Disbursed]]) -> 28439.315 | AC4: 45197 | AD4: =EDATE(Table1[[#This Row],[Disbursement_Date]],Table1[[#This Row],[Tenure_Months]]) -> 46293 | AE4: PDC
A5: CUST0004 | B5: Mahesh Patel | C5: 34499 | D5: =DATEDIF(Table1[[#This Row],[Date_of_Birth]],TODAY(),"Y") -> 31 | E5: Male | F5: 9541417711 | G5: 9882839238 | H5: 670, Lashkar, Gwalior | I5: Gwalior | J5: 667 | K5: 474001 | L5: XXXX-XXXX-2298 | M5: IWGEL7912F | N5: Complete | O5: Self-Employed | P5: 30000 | Q5: Hero | R5: Splendor | S5: Two-Wheeler | T5: RJ80BA9856 | U5: 50000 | V5: BR004 | W5: Gwalior | X5: Neha Mishra | Y5: 35571 | Z5: 48 | AA5: 13.36 | AB5: =-PMT((Table1[[#This Row],[Interest_Rate_%]]/100)/12,Table1[[#This Row],[Tenure_Months]],Table1[[#This Row],[Amount_Disbursed]]) -> 960.64883 | AC5: 46014 | AD5: =EDATE(Table1[[#This Row],[Disbursement_Date]],Table1[[#This Row],[Tenure_Months]]) -> 47475 | AE5: NACH
A6: CUST0005 | B6: Santosh Mishra | C6: 33653 | D6: =DATEDIF(Table1[[#This Row],[Date_of_Birth]],TODAY(),"Y") -> 34 | E6: Male | F6: 9364371717 | G6: 9142672287 | H6: 958, Chorhata, Rewa | I6: Rewa | J6: 705 | K6: 486002 | L6: XXXX-XXXX-6331 | M6: IGDQL2188A | N6: Pending | O6: Business | P6: 100000 | Q6: Maruti | R6: Dzire | S6: Sedan | T6: CG37EC6718 | U6: 659602 | V6: BR005 | W6: Rewa | X6: Anita Dubey | Y6: 494849 | Z6: 12 | AA6: 11.05 | AB6: =-PMT((Table1[[#This Row],[Interest_Rate_%]]/100)/12,Table1[[#This Row],[Tenure_Months]],Table1[[#This Row],[Amount_Disbursed]]) -> 43747.117 | AC6: 45794 | AD6: =EDATE(Table1[[#This Row],[Disbursement_Date]],Table1[[#This Row],[Tenure_Months]]) -> 46159 | AE6: ECS
A7: CUST0006 | B7: Deepak Malviya | C7: 34578 | D7: =DATEDIF(Table1[[#This Row],[Date_of_Birth]],TODAY(),"Y") -> 31 | E7: Male | F7: 9220123666 | H7: 855, Adhartal, Jabalpur | I7: Jabalpur | J7: 793 | K7: 482005 | L7: XXXX-XXXX-7170 | M7: LBJYZ1653L | N7: Complete | O7: Business | P7: 30000 | Q7: Honda | R7: Activa | S7: Two-Wheeler | T7: MH81GC4878 | U7: 50000 | V7: BR003 | W7: Jabalpur | X7: Vikas Singh | Y7: 38984 | Z7: 24 | AA7: 15.69 | AB7: =-PMT((Table1[[#This Row],[Interest_Rate_%]]/100)/12,Table1[[#This Row],[Tenure_Months]],Table1[[#This Row],[Amount_Disbursed]]) -> 1903.0086 | AC7: 45498 | AD7: =EDATE(Table1[[#This Row],[Disbursement_Date]],Table1[[#This Row],[Tenure_Months]]) -> 46228 | AE7: ECS
A8: CUST0008 | B8: Dinesh Sharma | C8: 25309 | D8: =DATEDIF(Table1[[#This Row],[Date_of_Birth]],TODAY(),"Y") -> 57 | E8: Male | F8: 9756350429 | G8: 9178198716 | H8: 736, TT Nagar, Bhopal | I8: Bhopal | J8: 718 | K8: 462004 | L8: XXXX-XXXX-8323 | M8: DRXWX7965H | N8: Complete | O8: Business | P8: 75000 | Q8: Honda | R8: City | S8: Sedan | T8: CG41BH3184 | U8: 1156582 | V8: BR002 | W8: Bhopal | X8: Rohit Gupta | Y8: 872459 | Z8: 24 | AA8: 15.86 | AB8: =-PMT((Table1[[#This Row],[Interest_Rate_%]]/100)/12,Table1[[#This Row],[Tenure_Months]],Table1[[#This Row],[Amount_Disbursed]]) -> 42659.968 | AC8: 45092 | AD8: =EDATE(Table1[[#This Row],[Disbursement_Date]],Table1[[#This Row],[Tenure_Months]]) -> 45823 | AE8: NACH
A9: CUST0009 | B9: Meena Gupta | C9: 34161 | D9: =DATEDIF(Table1[[#This Row],[Date_of_Birth]],TODAY(),"Y") -> 32 | E9: Female | F9: 9682624278 | G9: 9166857303 | H9: 927, Habibganj, Bhopal | I9: Bhopal | J9: 786 | K9: 462006 | L9: XXXX-XXXX-4309 | M9: OMYHK7865R | N9: Expired | O9: Business | P9: 30000 | Q9: Honda | R9: City | S9: Sedan | T9: MH65HA7371 | U9: 1178760 | V9: BR002 | W9: Bhopal | X9: Rohit Gupta | Y9: 936007 | Z9: 60 | AA9: 13.74 | AB9: =-PMT((Table1[[#This Row],[Interest_Rate_%]]/100)/12,Table1[[#This Row],[Tenure_Months]],Table1[[#This Row],[Amount_Disbursed]]) -> 21653.284 | AC9: 45643 | AD9: =EDATE(Table1[[#This Row],[Disbursement_Date]],Table1[[#This Row],[Tenure_Months]]) -> 47469 | AE9: NACH
A10: CUST0011 | B10: Naresh Dwivedi | C10: 33390 | D10: =DATEDIF(Table1[[#This Row],[Date_of_Birth]],TODAY(),"Y") -> 35 | E10: Male | F10: 9630757561 | G10: 9295249057 | H10: 349, Kolar Road, Bhopal | I10: Bhopal | J10: 690 | K10: 462005 | L10: XXXX-XXXX-0529 | M10: AYCSM4937W | N10: Pending | O10: Business | P10: 60000 | Q10: Honda | R10: City | S10: Sedan | T10: MP47DG4986 | U10: 1152260 | V10: BR002 | W10: Bhopal | X10: Rohit Gupta | Y10: 874852 | Z10: 24 | AA10: 11.58 | AB10: =-PMT((Table1[[#This Row],[Interest_Rate_%]]/100)/12,Table1[[#This Row],[Tenure_Months]],Table1[[#This Row],[Amount_Disbursed]]) -> 41010.94 | AC10: 44955 | AD10: =EDATE(Table1[[#This Row],[Disbursement_Date]],Table1[[#This Row],[Tenure_Months]]) -> 45686 | AE10: PDC
A11: CUST0012 | B11: Asha Singh | C11: 35854 | D11: =DATEDIF(Table1[[#This Row],[Date_of_Birth]],TODAY(),"Y") -> 28 | E11: Female | F11: 9113169872 | G11: 9604011128 | H11: 989, MG Road, Indore | I11: Indore | J11: 785 | K11: 452003 | L11: XXXX-XXXX-2836 | M11: VKBQB3444Z | N11: Expired | O11: Self-Employed | P11: 20000 | Q11: Hyundai | R11: i20 | S11: Hatchback | T11: CG63DJ7232 | U11: 715525 | V11: BR001 | W11: Indore | X11: Amit Sharma | Y11: 599235 | Z11: 24 | AA11: 15.23 | AB11: =-PMT((Table1[[#This Row],[Interest_Rate_%]]/100)/12,Table1[[#This Row],[Tenure_Months]],Table1[[#This Row],[Amount_Disbursed]]) -> 29120.422 | AC11: 45332 | AD11: =EDATE(Table1[[#This Row],[Disbursement_Date]],Table1[[#This Row],[Tenure_Months]]) -> 46063 | AE11: ECS
A12: CUST0013 | B12: Ramesh Verma | C12: 28265 | D12: =DATEDIF(Table1[[#This Row],[Date_of_Birth]],TODAY(),"Y") -> 49 | E12: Male | F12: 9904187231 | G12: 9409893263 | H12: 717, Gorakhpur, Jabalpur | I12: Jabalpur | J12: 672 | K12: 482003 | L12: XXXX-XXXX-8490 | M12: MCBLI5102A | N12: Complete | O12: Salaried | P12: 100000 | Q12: Maruti | R12: Swift | S12: Hatchback | T12: MH83AC8708 | U12: 688117 | V12: BR003 | W12: Jabalpur | X12: Kavita Yadav | Y12: 538554 | Z12: 18 | AA12: 13.61 | AB12: =-PMT((Table1[[#This Row],[Interest_Rate_%]]/100)/12,Table1[[#This Row],[Tenure_Months]],Table1[[#This Row],[Amount_Disbursed]]) -> 33246.325 | AC12: 45947 | AD12: =EDATE(Table1[[#This Row],[Disbursement_Date]],Table1[[#This Row],[Tenure_Months]]) -> 46494 | AE12: PDC
A13: CUST0014 | B13: Ajay Chauhan | C13: 35827 | D13: =DATEDIF(Table1[[#This Row],[Date_of_Birth]],TODAY(),"Y") -> 28 | E13: Male | F13: 9776481264 | G13: 9356943695 | H13: 566, Purani Basti, Rewa | I13: Rewa | J13: 746 | K13: 486001 | L13: XXXX-XXXX-2733 | M13: YQEYH5479N | N13: Pending | O13: Self-Employed | P13: 30000 | Q13: Honda | R13: City | S13: Sedan | T13: UP59DJ3236 | U13: 1222255 | V13: BR005 | W13: Rewa | X13: Anita Dubey | Y13: 866248 | Z13: 60 | AA13: 13.34 | AB13: =-PMT((Table1[[#This Row],[Interest_Rate_%]]/100)/12,Table1[[#This Row],[Tenure_Months]],Table1[[#This Row],[Amount_Disbursed]]) -> 19860.902 | AC13: 45707 | AD13: =EDATE(Table1[[#This Row],[Disbursement_Date]],Table1[[#This Row],[Tenure_Months]]) -> 47533 | AE13: ECS
A14: CUST0015 | B14: Seema Joshi | C14: 26880 | D14: =DATEDIF(Table1[[#This Row],[Date_of_Birth]],TODAY(),"Y") -> 52 | E14: Female | F14: 9664735673 | G14: 9116479358 | H14: 77, TT Nagar, Bhopal | I14: Bhopal | J14: 638 | K14: 462003 | L14: XXXX-XXXX-9489 | M14: SQWWW7226K | N14: Pending | O14: Business | P14: 15000 | Q14: Renault | R14: Kwid | S14: Hatchback | T14: UP90ED2480 | U14: 458968 | V14: BR002 | W14: Bhopal | X14: Sunita Patel | Y14: 363463 | Z14: 60 | AA14: 10.56 | AB14: =-PMT((Table1[[#This Row],[Interest_Rate_%]]/100)/12,Table1[[#This Row],[Tenure_Months]],Table1[[#This Row],[Amount_Disbursed]]) -> 7823.045 | AC14: 45879 | AD14: =EDATE(Table1[[#This Row],[Disbursement_Date]],Table1[[#This Row],[Tenure_Months]]) -> 47705 | AE14: ECS
A15: CUST0016 | B15: Asha Jain | C15: 30556 | D15: =DATEDIF(Table1[[#This Row],[Date_of_Birth]],TODAY(),"Y") -> 42 | E15: Female | F15: 9424400672 | H15: 243, Gorakhpur, Jabalpur | I15: Jabalpur | J15: 656 | K15: 482005 | L15: XXXX-XXXX-0353 | M15: HSAVK1132S | N15: Complete | O15: Business | P15: 60000 | Q15: Hero | R15: Splendor | S15: Two-Wheeler | T15: UP87FD4115 | U15: 62512 | V15: BR003 | W15: Jabalpur | X15: Kavita Yadav | Y15: 55853 | Z15: 24 | AA15: 14.98 | AB15: =-PMT((Table1[[#This Row],[Interest_Rate_%]]/100)/12,Table1[[#This Row],[Tenure_Months]],Table1[[#This Row],[Amount_Disbursed]]) -> 2707.5941 | AC15: 45620 | AD15: =EDATE(Table1[[#This Row],[Disbursement_Date]],Table1[[#This Row],[Tenure_Months]]) -> 46350 | AE15: NACH
A16: CUST0017 | B16: Lata Gupta | C16: 33612 | D16: =DATEDIF(Table1[[#This Row],[Date_of_Birth]],TODAY(),"Y") -> 34 | E16: Female | F16: 9676140134 | H16: 599, Thatipur, Gwalior | I16: Gwalior | J16: 736 | K16: 474006 | L16: XXXX-XXXX-6063 | M16: CGAWO4626U | N16: Complete | O16: Business | P16: 60000 | Q16: TVS | R16: Jupiter | S16: Two-Wheeler | T16: RJ24CA1609 | U16: 79608 | V16: BR004 | W16: Gwalior | X16: Neha Mishra | Y16: 64394 | Z16: 60 | AA16: 12.65 | AB16: =-PMT((Table1[[#This Row],[Interest_Rate_%]]/100)/12,Table1[[#This Row],[Tenure_Months]],Table1[[#This Row],[Amount_Disbursed]]) -> 1453.6499 | AC16: 45742 | AD16: =EDATE(Table1[[#This Row],[Disbursement_Date]],Table1[[#This Row],[Tenure_Months]]) -> 47568 | AE16: ECS
A17: CUST0018 | B17: Kiran Sharma | C17: 25727 | D17: =DATEDIF(Table1[[#This Row],[Date_of_Birth]],TODAY(),"Y") -> 55 | E17: Female | F17: 9235209737 | G17: 9320337809 | H17: 784, Habibganj, Bhopal | I17: Bhopal | J17: 775 | K17: 462002 | L17: XXXX-XXXX-7466 | M17: VGUUP5542E | N17: Complete | O17: Business | P17: 35000 | Q17: Bajaj | R17: Pulsar | S17: Two-Wheeler | T17: MP94AC1243 | U17: 92871 | V17: BR002 | W17: Bhopal | X17: Sunita Patel | Y17: 77753 | Z17: 36 | AA17: 14.77 | AB17: =-PMT((Table1[[#This Row],[Interest_Rate_%]]/100)/12,Table1[[#This Row],[Tenure_Months]],Table1[[#This Row],[Amount_Disbursed]]) -> 2686.5841 | AC17: 45835 | AD17: =EDATE(Table1[[#This Row],[Disbursement_Date]],Table1[[#This Row],[Tenure_Months]]) -> 46931 | AE17: NACH
A18: CUST0020 | B18: Kiran Dwivedi | C18: 37276 | D18: =DATEDIF(Table1[[#This Row],[Date_of_Birth]],TODAY(),"Y") -> 24 | E18: Female | F18: 9806340901 | G18: 9387169808 | H18: 280, Morar, Gwalior | I18: Gwalior | J18: 756 | K18: 474003 | L18: XXXX-XXXX-1424 | M18: EDRBT1502C | N18: Expired | O18: Salaried | P18: 50000 | Q18: Honda | R18: City | S18: Sedan | T18: UP57EF2391 | U18: 1194681 | V18: BR004 | W18: Gwalior | X18: Neha Mishra | Y18: 905436 | Z18: 12 | AA18: 10.55 | AB18: =-PMT((Table1[[#This Row],[Interest_Rate_%]]/100)/12,Table1[[#This Row],[Tenure_Months]],Table1[[#This Row],[Amount_Disbursed]]) -> 79834.006 | AC18: 45808 | AD18: =EDATE(Table1[[#This Row],[Disbursement_Date]],Table1[[#This Row],[Tenure_Months]]) -> 46173 | AE18: NACH
A19: CUST0021 | B19: Renu Soni | C19: 26142 | D19: =DATEDIF(Table1[[#This Row],[Date_of_Birth]],TODAY(),"Y") -> 54 | E19: Female | F19: 9896760809 | H19: 944, MP Nagar, Bhopal | I19: Bhopal | J19: 732 | K19: 462003 | L19: XXXX-XXXX-2032 | M19: OSKCA6321F | N19: Expired | O19: Self-Employed | P19: 40000 | Q19: Maruti | R19: Dzire | S19: Sedan | T19: MP41GG9584 | U19: 707240 | V19: BR002 | W19: Bhopal | X19: Sunita Patel | Y19: 591412 | Z19: 48 | AA19: 14.36 | AB19: =-PMT((Table1[[#This Row],[Interest_Rate_%]]/100)/12,Table1[[#This Row],[Tenure_Months]],Table1[[#This Row],[Amount_Disbursed]]) -> 16268.21 | AC19: 45588 | AD19: =EDATE(Table1[[#This Row],[Disbursement_Date]],Table1[[#This Row],[Tenure_Months]]) -> 47049 | AE19: PDC
A20: CUST0022 | B20: Pradeep Pandey | C20: 30957 | D20: =DATEDIF(Table1[[#This Row],[Date_of_Birth]],TODAY(),"Y") -> 41 | E20: Male | F20: 9477895080 | G20: 9433297890 | H20: 378, Morar, Gwalior | I20: Gwalior | J20: 653 | K20: 474001 | L20: XXXX-XXXX-6009 | M20: PJPYT1672O | N20: Expired | O20: Business | P20: 30000 | Q20: Tata | R20: Nexon | S20: SUV | T20: RJ74CA8381 | U20: 1029299 | V20: BR004 | W20: Gwalior | X20: Neha Mishra | Y20: 737287 | Z20: 60 | AA20: 11.35 | AB20: =-PMT((Table1[[#This Row],[Interest_Rate_%]]/100)/12,Table1[[#This Row],[Tenure_Months]],Table1[[#This Row],[Amount_Disbursed]]) -> 16159.398 | AC20: 45643 | AD20: =EDATE(Table1[[#This Row],[Disbursement_Date]],Table1[[#This Row],[Tenure_Months]]) -> 47469 | AE20: ECS
A21: CUST0023 | B21: Mohit Agarwal | C21: 32224 | D21: =DATEDIF(Table1[[#This Row],[Date_of_Birth]],TODAY(),"Y") -> 38 | E21: Male | F21: 9854658900 | G21: 9893253262 | H21: 662, Malviya Nagar, Indore | I21: Indore | J21: 633 | K21: 452005 | L21: XXXX-XXXX-9032 | M21: JEFYM4711E | N21: Complete | O21: Salaried | P21: 20000 | Q21: Mahindra | R21: Bolero | S21: MUV | T21: CG14FC7172 | U21: 970748 | V21: BR001 | W21: Indore | X21: Priya Verma | Y21: 777162 | Z21: 36 | AA21: 16.3 | AB21: =-PMT((Table1[[#This Row],[Interest_Rate_%]]/100)/12,Table1[[#This Row],[Tenure_Months]],Table1[[#This Row],[Amount_Disbursed]]) -> 27437.956 | AC21: 45335 | AD21: =EDATE(Table1[[#This Row],[Disbursement_Date]],Table1[[#This Row],[Tenure_Months]]) -> 46431 | AE21: PDC
A22: CUST0024 | B22: Mohit Patel | C22: 36566 | D22: =DATEDIF(Table1[[#This Row],[Date_of_Birth]],TODAY(),"Y") -> 26 | E22: Male | F22: 9190060226 | G22: 9392907427 | H22: 851, Thatipur, Gwalior | I22: Gwalior | J22: 777 | K22: 474001 | L22: XXXX-XXXX-0842 | M22: LJABN4862M | N22: Complete | O22: Self-Employed | P22: 30000 | Q22: Maruti | R22: Swift | S22: Hatchback | T22: MP93FC3254 | U22: 641770 | V22: BR004 | W22: Gwalior | X22: Sanjay Tiwari | Y22: 530352 | Z22: 48 | AA22: 11.95 | AB22: =-PMT((Table1[[#This Row],[Interest_Rate_%]]/100)/12,Table1[[#This Row],[Tenure_Months]],Table1[[#This Row],[Amount_Disbursed]]) -> 13953.186 | AC22: 45221 | AD22: =EDATE(Table1[[#This Row],[Disbursement_Date]],Table1[[#This Row],[Tenure_Months]]) -> 46682 | AE22: ECS
A23: CUST0025 | B23: Pushpa Yadav | C23: 26554 | D23: =DATEDIF(Table1[[#This Row],[Date_of_Birth]],TODAY(),"Y") -> 53 | E23: Female | F23: 9172670118 | G23: 9684203557 | H23: 400, TT Nagar, Bhopal | I23: Bhopal | J23: 797 | K23: 462001 | L23: XXXX-XXXX-7563 | M23: ZGAUI2698Y | N23: Expired | O23: Business | P23: 40000 | Q23: Maruti | R23: Brezza | S23: SUV | T23: MH79FC8612 | U23: 1055811 | V23: BR002 | W23: Bhopal | X23: Sunita Patel | Y23: 926893 | Z23: 60 | AA23: 13.14 | AB23: =-PMT((Table1[[#This Row],[Interest_Rate_%]]/100)/12,Table1[[#This Row],[Tenure_Months]],Table1[[#This Row],[Amount_Disbursed]]) -> 21156.152 | AC23: 45718 | AD23: =EDATE(Table1[[#This Row],[Disbursement_Date]],Table1[[#This Row],[Tenure_Months]]) -> 47544 | AE23: ECS
A24: CUST0026 | B24: Neha Gupta | C24: 34379 | D24: =DATEDIF(Table1[[#This Row],[Date_of_Birth]],TODAY(),"Y") -> 32 | E24: Female | F24: 9746879296 | G24: 9293763673 | H24: 82, Adhartal, Jabalpur | I24: Jabalpur | J24: 651 | K24: 482006 | L24: XXXX-XXXX-3022 | M24: LSELL6776T | N24: Pending | O24: Self-Employed | P24: 15000 | Q24: Maruti | R24: Dzire | S24: Sedan | T24: RJ56CA3339 | U24: 737973 | V24: BR003 | W24: Jabalpur | X24: Kavita Yadav | Y24: 630961 | Z24: 60 | AA24: 13.18 | AB24: =-PMT((Table1[[#This Row],[Interest_Rate_%]]/100)/12,Table1[[#This Row],[Tenure_Months]],Table1[[#This Row],[Amount_Disbursed]]) -> 14414.508 | AC24: 45511 | AD24: =EDATE(Table1[[#This Row],[Disbursement_Date]],Table1[[#This Row],[Tenure_Months]]) -> 47337 | AE24: PDC
A25: CUST0027 | B25: Amit Chauhan | C25: 26631 | D25: =DATEDIF(Table1[[#This Row],[Date_of_Birth]],TODAY(),"Y") -> 53 | E25: Male | F25: 9443154754 | G25: 9861863296 | H25: 556, Palasia, Indore | I25: Indore | J25: 640 | K25: 452003 | L25: XXXX-XXXX-4013 | M25: SYQUN2988G | N25: Complete | O25: Salaried | P25: 15000 | Q25: Tata | R25: Nexon | S25: SUV | T25: CG57HJ3126 | U25: 1022616 | V25: BR001 | W25: Indore | X25: Amit Sharma | Y25: 778031 | Z25: 18 | AA25: 12.44 | AB25: =-PMT((Table1[[#This Row],[Interest_Rate_%]]/100)/12,Table1[[#This Row],[Tenure_Months]],Table1[[#This Row],[Amount_Disbursed]]) -> 47605.1 | AC25: 45388 | AD25: =EDATE(Table1[[#This Row],[Disbursement_Date]],Table1[[#This Row],[Tenure_Months]]) -> 45936 | AE25: ECS
A26: CUST0028 | B26: Renu Dubey | C26: 27708 | D26: =DATEDIF(Table1[[#This Row],[Date_of_Birth]],TODAY(),"Y") -> 50 | E26: Female | F26: 9759737342 | G26: 9639633807 | H26: 176, Habibganj, Bhopal | I26: Bhopal | J26: 668 | K26: 462006 | L26: XXXX-XXXX-7914 | M26: IYBWC5336U | N26: Complete | O26: Business | P26: 50000 | Q26: Renault | R26: Kwid | S26: Hatchback | T26: MP73EE8912 | U26: 533753 | V26: BR002 | W26: Bhopal | X26: Sunita Patel | Y26: 474547 | Z26: 48 | AA26: 13.01 | AB26: =-PMT((Table1[[#This Row],[Interest_Rate_%]]/100)/12,Table1[[#This Row],[Tenure_Months]],Table1[[#This Row],[Amount_Disbursed]]) -> 12733.263 | AC26: 45254 | AD26: =EDATE(Table1[[#This Row],[Disbursement_Date]],Table1[[#This Row],[Tenure_Months]]) -> 46715 | AE26: ECS
A27: CUST0029 | B27: Nisha Rajput | C27: 31625 | D27: =DATEDIF(Table1[[#This Row],[Date_of_Birth]],TODAY(),"Y") -> 39 | E27: Female | F27: 9196689473 | G27: 9642716859 | H27: 598, Morar, Gwalior | I27: Gwalior | J27: 771 | K27: 474001 | L27: XXXX-XXXX-4700 | M27: MWRMN2761N | N27: Complete | O27: Self-Employed | P27: 40000 | Q27: Bajaj | R27: Pulsar | S27: Two-Wheeler | T27: MH15GA4189 | U27: 122855 | V27: BR004 | W27: Gwalior | X27: Sanjay Tiwari | Y27: 94056 | Z27: 48 | AA27: 12.41 | AB27: =-PMT((Table1[[#This Row],[Interest_Rate_%]]/100)/12,Table1[[#This Row],[Tenure_Months]],Table1[[#This Row],[Amount_Disbursed]]) -> 2495.8315 | AC27: 45731 | AD27: =EDATE(Table1[[#This Row],[Disbursement_Date]],Table1[[#This Row],[Tenure_Months]]) -> 47192 | AE27: PDC
A28: CUST0030 | B28: Renu Rajput | C28: 37757 | D28: =DATEDIF(Table1[[#This Row],[Date_of_Birth]],TODAY(),"Y") -> 23 | E28: Female | F28: 9975903641 | H28: 598, Chorhata, Rewa | I28: Rewa | J28: 800 | K28: 486006 | L28: XXXX-XXXX-1269 | M28: QPGRZ4728X | N28: Complete | O28: Business | P28: 60000 | Q28: Maruti | R28: Brezza | S28: SUV | T28: CG58CD1517 | U28: 1118712 | V28: BR005 | W28: Rewa | X28: Anita Dubey | Y28: 826116 | Z28: 18 | AA28: 12.17 | AB28: =-PMT((Table1[[#This Row],[Interest_Rate_%]]/100)/12,Table1[[#This Row],[Tenure_Months]],Table1[[#This Row],[Amount_Disbursed]]) -> 50443.508 | AC28: 45538 | AD28: =EDATE(Table1[[#This Row],[Disbursement_Date]],Table1[[#This Row],[Tenure_Months]]) -> 46084 | AE28: NACH
A29: CUST0032 | B29: Rajesh Pandey | C29: 37898 | D29: =DATEDIF(Table1[[#This Row],[Date_of_Birth]],TODAY(),"Y") -> 22 | E29: Male | F29: 9459748735 | H29: 911, Civil Lines, Jabalpur | I29: Jabalpur | J29: 659 | K29: 482005 | L29: XXXX-XXXX-7342 | M29: FCELG4050A | N29: Complete | O29: Self-Employed | P29: 100000 | Q29: Honda | R29: Activa | S29: Two-Wheeler | T29: UP32GG9442 | U29: 134258 | V29: BR003 | W29: Jabalpur | X29: Vikas Singh | Y29: 111131 | Z29: 24 | AA29: 12.71 | AB29: =-PMT((Table1[[#This Row],[Interest_Rate_%]]/100)/12,Table1[[#This Row],[Tenure_Months]],Table1[[#This Row],[Amount_Disbursed]]) -> 5268.2453 | AC29: 45379 | AD29: =EDATE(Table1[[#This Row],[Disbursement_Date]],Table1[[#This Row],[Tenure_Months]]) -> 46109 | AE29: NACH
A30: CUST0033 | B30: Vikas Malviya | C30: 35699 | D30: =DATEDIF(Table1[[#This Row],[Date_of_Birth]],TODAY(),"Y") -> 28 | E30: Male | F30: 9813065972 | G30: 9918040539 | H30: 539, Purani Basti, Rewa | I30: Rewa | J30: 787 | K30: 486005 | L30: XXXX-XXXX-3734 | M30: COBON9792E | N30: Complete | O30: Self-Employed | P30: 75000 | Q30: Honda | R30: City | S30: Sedan | T30: UP84HB9361 | U30: 1165235 | V30: BR005 | W30: Rewa | X30: Anita Dubey | Y30: 902931 | Z30: 36 | AA30: 13.19 | AB30: =-PMT((Table1[[#This Row],[Interest_Rate_%]]/100)/12,Table1[[#This Row],[Tenure_Months]],Table1[[#This Row],[Amount_Disbursed]]) -> 30506.012 | AC30: 45700 | AD30: =EDATE(Table1[[#This Row],[Disbursement_Date]],Table1[[#This Row],[Tenure_Months]]) -> 46795 | AE30: ECS
A31: CUST0034 | B31: Mohit Agarwal | C31: 36609 | D31: =DATEDIF(Table1[[#This Row],[Date_of_Birth]],TODAY(),"Y") -> 26 | E31: Male | F31: 9339111798 | G31: 9911941471 | H31: 306, Malviya Nagar, Indore | I31: Indore | J31: 762 | K31: 452006 | L31: XXXX-XXXX-9243 | M31: LJFLE4088X | N31: Complete | O31: Salaried | P31: 100000 | Q31: Bajaj | R31: Pulsar | S31: Two-Wheeler | T31: UP36BB1550 | U31: 72050 | V31: BR001 | W31: Indore | X31: Amit Sharma | Y31: 58457 | Z31: 48 | AA31: 15.78 | AB31: =-PMT((Table1[[#This Row],[Interest_Rate_%]]/100)/12,Table1[[#This Row],[Tenure_Months]],Table1[[#This Row],[Amount_Disbursed]]) -> 1650.1086 | AC31: 45285 | AD31: =EDATE(Table1[[#This Row],[Disbursement_Date]],Table1[[#This Row],[Tenure_Months]]) -> 46746 | AE31: PDC
A32: CUST0035 | B32: Pradeep Agarwal | C32: 36700 | D32: =DATEDIF(Table1[[#This Row],[Date_of_Birth]],TODAY(),"Y") -> 25 | E32: Male | F32: 9547025173 | G32: 9422002819 | H32: 247, Vijay Nagar, Indore | I32: Indore | J32: 698 | K32: 452003 | L32: XXXX-XXXX-2156 | M32: DMBKK9683E | N32: Pending | O32: Salaried | P32: 30000 | Q32: Tata | R32: Nexon | S32: SUV | T32: MP67FB9775 | U32: 1034765 | V32: BR001 | W32: Indore | X32: Priya Verma | Y32: 913723 | Z32: 48 | AA32: 12.43 | AB32: =-PMT((Table1[[#This Row],[Interest_Rate_%]]/100)/12,Table1[[#This Row],[Tenure_Months]],Table1[[#This Row],[Amount_Disbursed]]) -> 24255.193 | AC32: 45506 | AD32: =EDATE(Table1[[#This Row],[Disbursement_Date]],Table1[[#This Row],[Tenure_Months]]) -> 46967 | AE32: ECS
A33: CUST0036 | B33: Savita Chauhan | C33: 27014 | D33: =DATEDIF(Table1[[#This Row],[Date_of_Birth]],TODAY(),"Y") -> 52 | E33: Female | F33: 9917792874 | G33: 9318106480 | H33: 577, Civil Lines, Jabalpur | I33: Jabalpur | J33: 757 | K33: 482006 | L33: XXXX-XXXX-2466 | M33: GYPKD6404H | N33: Pending | O33: Business | P33: 30000 | Q33: Honda | R33: City | S33: Sedan | T33: MH42HH8550 | U33: 1222173 | V33: BR003 | W33: Jabalpur | X33: Kavita Yadav | Y33: 859366 | Z33: 48 | AA33: 13.81 | AB33: =-PMT((Table1[[#This Row],[Interest_Rate_%]]/100)/12,Table1[[#This Row],[Tenure_Months]],Table1[[#This Row],[Amount_Disbursed]]) -> 23401.621 | AC33: 44951 | AD33: =EDATE(Table1[[#This Row],[Disbursement_Date]],Table1[[#This Row],[Tenure_Months]]) -> 46412 | AE33: NACH
A34: CUST0037 | B34: Pushpa Yadav | C34: 26712 | D34: =DATEDIF(Table1[[#This Row],[Date_of_Birth]],TODAY(),"Y") -> 53 | E34: Female | F34: 9259877461 | H34: 274, Malviya Nagar, Indore | I34: Indore | J34: 718 | K34: 452001 | L34: XXXX-XXXX-8076 | M34: OZFRW1519C | N34: Pending | O34: Self-Employed | P34: 50000 | Q34: Mahindra | R34: Bolero | S34: MUV | T34: MP91AC2354 | U34: 962390 | V34: BR001 | W34: Indore | X34: Amit Sharma | Y34: 731277 | Z34: 48 | AA34: 11.94 | AB34: =-PMT((Table1[[#This Row],[Interest_Rate_%]]/100)/12,Table1[[#This Row],[Tenure_Months]],Table1[[#This Row],[Amount_Disbursed]]) -> 19235.792 | AC34: 45723 | AD34: =EDATE(Table1[[#This Row],[Disbursement_Date]],Table1[[#This Row],[Tenure_Months]]) -> 47184 | AE34: PDC
A35: CUST0038 | B35: Kavita Thakur | C35: 32512 | D35: =DATEDIF(Table1[[#This Row],[Date_of_Birth]],TODAY(),"Y") -> 37 | E35: Female | F35: 9569319938 | H35: 620, Habibganj, Bhopal | I35: Bhopal | J35: 795 | K35: 462005 | L35: XXXX-XXXX-8633 | M35: AHZMJ7150N | N35: Complete | O35: Business | P35: 100000 | Q35: Honda | R35: Activa | S35: Two-Wheeler | T35: MP89ED2204 | U35: 84816 | V35: BR002 | W35: Bhopal | X35: Sunita Patel | Y35: 65949 | Z35: 12 | AA35: 14.85 | AB35: =-PMT((Table1[[#This Row],[Interest_Rate_%]]/100)/12,Table1[[#This Row],[Tenure_Months]],Table1[[#This Row],[Amount_Disbursed]]) -> 5947.7785 | AC35: 45424 | AD35: =EDATE(Table1[[#This Row],[Disbursement_Date]],Table1[[#This Row],[Tenure_Months]]) -> 45789 | AE35: PDC
A36: CUST0039 | B36: Vijay Pandey | C36: 30899 | D36: =DATEDIF(Table1[[#This Row],[Date_of_Birth]],TODAY(),"Y") -> 41 | E36: Male | F36: 9167932588 | H36: 802, MP Nagar, Bhopal | I36: Bhopal | J36: 782 | K36: 462003 | L36: XXXX-XXXX-8722 | M36: QPFCH7483K | N36: Expired | O36: Self-Employed | P36: 40000 | Q36: Honda | R36: City | S36: Sedan | T36: RJ93CE6253 | U36: 1193874 | V36: BR002 | W36: Bhopal | X36: Sunita Patel | Y36: 1026179 | Z36: 60 | AA36: 10.91 | AB36: =-PMT((Table1[[#This Row],[Interest_Rate_%]]/100)/12,Table1[[#This Row],[Tenure_Months]],Table1[[#This Row],[Amount_Disbursed]]) -> 22265.587 | AC36: 45764 | AD36: =EDATE(Table1[[#This Row],[Disbursement_Date]],Table1[[#This Row],[Tenure_Months]]) -> 47590 | AE36: PDC
A37: CUST0041 | B37: Rekha Mishra | C37: 36603 | D37: =DATEDIF(Table1[[#This Row],[Date_of_Birth]],TODAY(),"Y") -> 26 | E37: Female | F37: 9271944408 | G37: 9557810637 | H37: 645, Vijay Nagar, Indore | I37: Indore | J37: 693 | K37: 452002 | L37: XXXX-XXXX-1537 | M37: LAPFP7370A | N37: Complete | O37: Salaried | P37: 20000 | Q37: Renault | R37: Kwid | S37: Hatchback | T37: CG33FF4228 | U37: 463336 | V37: BR001 | W37: Indore | X37: Amit Sharma | Y37: 377600 | Z37: 36 | AA37: 11.61 | AB37: =-PMT((Table1[[#This Row],[Interest_Rate_%]]/100)/12,Table1[[#This Row],[Tenure_Months]],Table1[[#This Row],[Amount_Disbursed]]) -> 12471.504 | AC37: 45281 | AD37: =EDATE(Table1[[#This Row],[Disbursement_Date]],Table1[[#This Row],[Tenure_Months]]) -> 46377 | AE37: PDC
A38: CUST0042 | B38: Deepak Dwivedi | C38: 25720 | D38: =DATEDIF(Table1[[#This Row],[Date_of_Birth]],TODAY(),"Y") -> 56 | E38: Male | F38: 9620344871 | H38: 419, TT Nagar, Bhopal | I38: Bhopal | J38: 756 | K38: 462004 | L38: XXXX-XXXX-0733 | M38: EOUFA4683R | N38: Complete | O38: Salaried | P38: 100000 | Q38: TVS | R38: Jupiter | S38: Two-Wheeler | T38: CG75BB5389 | U38: 104921 | V38: BR002 | W38: Bhopal | X38: Sunita Patel | Y38: 76927 | Z38: 18 | AA38: 15.21 | AB38: =-PMT((Table1[[#This Row],[Interest_Rate_%]]/100)/12,Table1[[#This Row],[Tenure_Months]],Table1[[#This Row],[Amount_Disbursed]]) -> 4806.6808 | AC38: 45350 | AD38: =EDATE(Table1[[#This Row],[Disbursement_Date]],Table1[[#This Row],[Tenure_Months]]) -> 45897 | AE38: NACH
A39: CUST0043 | B39: Rekha Joshi | C39: 31186 | D39: =DATEDIF(Table1[[#This Row],[Date_of_Birth]],TODAY(),"Y") -> 41 | E39: Female | F39: 9387057426 | G39: 9652348887 | H39: 139, Purani Basti, Rewa | I39: Rewa | J39: 631 | K39: 486001 | L39: XXXX-XXXX-6605 | M39: WDWGS5055Y | N39: Pending | O39: Self-Employed | P39: 25000 | Q39: Renault | R39: Kwid | S39: Hatchback | T39: MH90GG8405 | U39: 532890 | V39: BR005 | W39: Rewa | X39: Anita Dubey | Y39: 409020 | Z39: 48 | AA39: 11.28 | AB39: =-PMT((Table1[[#This Row],[Interest_Rate_%]]/100)/12,Table1[[#This Row],[Tenure_Months]],Table1[[#This Row],[Amount_Disbursed]]) -> 10627.039 | AC39: 45920 | AD39: =EDATE(Table1[[#This Row],[Disbursement_Date]],Table1[[#This Row],[Tenure_Months]]) -> 47381 | AE39: ECS
A40: CUST0044 | B40: Mahesh Yadav | C40: 34912 | D40: =DATEDIF(Table1[[#This Row],[Date_of_Birth]],TODAY(),"Y") -> 30 | E40: Male | F40: 9559346003 | H40: 163, Morar, Gwalior | I40: Gwalior | J40: 675 | K40: 474001 | L40: XXXX-XXXX-5144 | M40: GJXEK6005X | N40: Complete | O40: Self-Employed | P40: 20000 | Q40: TVS | R40: Jupiter | S40: Two-Wheeler | T40: MP37HB3174 | U40: 52475 | V40: BR004 | W40: Gwalior | X40: Neha Mishra | Y40: 40418 | Z40: 18 | AA40: 14.27 | AB40: =-PMT((Table1[[#This Row],[Interest_Rate_%]]/100)/12,Table1[[#This Row],[Tenure_Months]],Table1[[#This Row],[Amount_Disbursed]]) -> 2507.6042 | AC40: 45237 | AD40: =EDATE(Table1[[#This Row],[Disbursement_Date]],Table1[[#This Row],[Tenure_Months]]) -> 45784 | AE40: ECS
...

Sheet agent_master
A1: ABC Finance | Agent Master | May 2026
A2: Agent_Code | B2: Agent_Name | C2: Channel | D2: Branch_Code | E2: Branch_Name | F2: Team_Leader | G2: Joining_Date | H2: Status
A3: AG001 | B3: Mohit Mishra | C3: Field | D3: BR001 | E3: =_xlfn.XLOOKUP(Table4[[#This Row],[Branch_Code]],Table1[Branch_Code],Table1[Branch_Name],,0) -> Indore | F3: Rahul Sharma | G3: 45659 | H3: Active
A4: AG002 | B4: Sunita Patel | C4: Tele-Calling | D4: BR002 | E4: =_xlfn.XLOOKUP(Table4[[#This Row],[Branch_Code]],Table1[Branch_Code],Table1[Branch_Name],,0) -> Bhopal | F4: Priya Verma | G4: 45660 | H4: Active
A5: AG003 | B5: Pushpa Gupta | C5: Field | D5: BR003 | E5: =_xlfn.XLOOKUP(Table4[[#This Row],[Branch_Code]],Table1[Branch_Code],Table1[Branch_Name],,0) -> Jabalpur | F5: Sanjay Patel | G5: 45661 | H5: On Leave
A6: AG004 | B6: Pankaj Verma | C6: Tele-Calling | D6: BR004 | E6: =_xlfn.XLOOKUP(Table4[[#This Row],[Branch_Code]],Table1[Branch_Code],Table1[Branch_Name],,0) -> Gwalior | F6: Ankit Jain | G6: 45662 | H6: Active
A7: AG005 | B7: Amit Thakur | C7: Field | D7: BR005 | E7: =_xlfn.XLOOKUP(Table4[[#This Row],[Branch_Code]],Table1[Branch_Code],Table1[Branch_Name],,0) -> Rewa | F7: Rohit Gupta | G7: 45663 | H7: Active
A8: AG006 | B8: Suresh Malviya | C8: Field | D8: BR001 | E8: =_xlfn.XLOOKUP(Table4[[#This Row],[Branch_Code]],Table1[Branch_Code],Table1[Branch_Name],,0) -> Indore | F8: Rahul Sharma | G8: 45664 | H8: Active
A9: AG007 | B9: Pushpa Jain | C9: Tele-Calling | D9: BR002 | E9: =_xlfn.XLOOKUP(Table4[[#This Row],[Branch_Code]],Table1[Branch_Code],Table1[Branch_Name],,0) -> Bhopal | F9: Priya Verma | G9: 45665 | H9: Active
A10: AG008 | B10: Pooja Shukla | C10: Field | D10: BR003 | E10: =_xlfn.XLOOKUP(Table4[[#This Row],[Branch_Code]],Table1[Branch_Code],Table1[Branch_Name],,0) -> Jabalpur | F10: Sanjay Patel | G10: 45666 | H10: Active
A11: AG009 | B11: Pankaj Joshi | C11: Field | D11: BR004 | E11: =_xlfn.XLOOKUP(Table4[[#This Row],[Branch_Code]],Table1[Branch_Code],Table1[Branch_Name],,0) -> Gwalior | F11: Ankit Jain | G11: 45667 | H11: Active
A12: AG010 | B12: Kavita Tiwari | C12: Tele-Calling | D12: BR005 | E12: =_xlfn.XLOOKUP(Table4[[#This Row],[Branch_Code]],Table1[Branch_Code],Table1[Branch_Name],,0) -> Rewa | F12: Rohit Gupta | G12: 45668 | H12: Active
A13: AG011 | B13: Umesh Gupta | C13: Field | D13: BR001 | E13: =_xlfn.XLOOKUP(Table4[[#This Row],[Branch_Code]],Table1[Branch_Code],Table1[Branch_Name],,0) -> Indore | F13: Rahul Sharma | G13: 45669 | H13: Inactive
A14: AG012 | B14: Umesh Soni | C14: Tele-Calling | D14: BR002 | E14: =_xlfn.XLOOKUP(Table4[[#This Row],[Branch_Code]],Table1[Branch_Code],Table1[Branch_Name],,0) -> Bhopal | F14: Priya Verma | G14: 45670 | H14: Active
... A22: AG020 | B22: Vijay Tiwari | C22: Field | D22: BR005 | E22: =_xlfn.XLOOKUP(Table4[[#This Row],[Branch_Code]],Table1[Branch_Code],Table1[Branch_Name],,0) -> Rewa | F22: Rohit Gupta | G22: 45678 | H22: Active

Sheet loan_status_tracker
A1: ABC Finance | Loan Status Tracker | May 2026
A2: Customer_ID | B2: Customer_Name | C2: Branch_Name | D2: Vehicle_Make | E2: Vehicle_Model | F2: Loan_Amount | G2: EMI_Amount | H2: EMI_Due_May26 | I2: Amount_Received_May26 | J2: Overdue_Amount | K2: EMI_Due_Date | L2: Days_Past_Due | M2: DPD_Bucket | N2: Loan_Status
A3: CUST0001 | B3: =_xlfn.XLOOKUP(Table2[[#This Row],[Customer_ID]],Table1[Customer_ID],Table1[Customer_Name],,0,) -> Vijay Mishra | C3: =_xlfn.XLOOKUP(Table2[[#This Row],[Customer_ID]],Table1[Customer_ID],Table1[Branch_Name],,) -> Indore | D3: =_xlfn.XLOOKUP(Table2[[#This Row],[Customer_ID]],Table1[Customer_ID],Table1[Vehicle_Make],,0) -> Bajaj | E3: =_xlfn.XLOOKUP(Table2[[#This Row],[Customer_ID]],Table1[Customer_ID],Table1[Vehicle_Model],,) -> Pulsar | F3: =_xlfn.XLOOKUP(Table2[[#This Row],[Customer_ID]],Table1[Customer_ID],Table1[Amount_Disbursed],,) -> 54982 | G3: =_xlfn.XLOOKUP(Table2[[#This Row],[Customer_ID]],Table1[Customer_ID],Table1[EMI_Amount],,0) -> 1887.4434 | H3: =Table2[[#This Row],[EMI_Amount]] -> 1887.4434 | I3: 167 | J3: =Table2[[#This Row],[EMI_Due_May26]]-Table2[[#This Row],[Amount_Received_May26]] -> 1720.4434 | K3: =DATE(2026,5,DAY(Table1[[#This Row],[Maturity_Date]])) -> 46159 | L3: =IF(Table2[[#This Row],[Overdue_Amount]]<1,"",MAX(0,TODAY()-Table2[[#This Row],[EMI_Due_Date]])) -> 21 | M3: =IF(LEN(Table2[[#This Row],[Days_Past_Due]])=0,"Current", IF(Table2[[#This Row],[Days_Past_Due]]<=30,"1-30", IF(Table2[[#This Row],[Days_Past_Due]]<=60,"31-60", IF(Table2[[#This Row],[Days_Past_Due]]<=90,"61-90","90+")))) -> 1-30 | N3: {=_xlfn.IFS(Table2[[#This Row],[DPD_Bucket]]="1-30","Overdue",Table2[[#This Row],[DPD_Bucket]]="90+","NPA",Table2[[#This Row],[DPD_Bucket]]="Current","Active",Table2[[#This Row],[DPD_Bucket]]="31-60","Overdue")} -> Overdue
A4: CUST0003 | B4: =_xlfn.XLOOKUP(Table2[[#This Row],[Customer_ID]],Table1[Customer_ID],Table1[Customer_Name],,0,) -> Mamta Dwivedi | C4: =_xlfn.XLOOKUP(Table2[[#This Row],[Customer_ID]],Table1[Customer_ID],Table1[Branch_Name],,) -> Jabalpur | D4: =_xlfn.XLOOKUP(Table2[[#This Row],[Customer_ID]],Table1[Customer_ID],Table1[Vehicle_Make],,0) -> Maruti | E4: =_xlfn.XLOOKUP(Table2[[#This Row],[Customer_ID]],Table1[Customer_ID],Table1[Vehicle_Model],,) -> Brezza | F4: =_xlfn.XLOOKUP(Table2[[#This Row],[Customer_ID]],Table1[Customer_ID],Table1[Amount_Disbursed],,) -> 858828 | G4: =_xlfn.XLOOKUP(Table2[[#This Row],[Customer_ID]],Table1[Customer_ID],Table1[EMI_Amount],,0) -> 28439.315 | H4: =Table2[[#This Row],[EMI_Amount]] -> 28439.315 | I4: 28439 | J4: =Table2[[#This Row],[EMI_Due_May26]]-Table2[[#This Row],[Amount_Received_May26]] -> 0.31540488 | K4: =DATE(2026,5,DAY(Table1[[#This Row],[Maturity_Date]])) -> 46170 | L4: =IF(Table2[[#This Row],[Overdue_Amount]]<1,"",MAX(0,TODAY()-Table2[[#This Row],[EMI_Due_Date]])) | M4: =IF(LEN(Table2[[#This Row],[Days_Past_Due]])=0,"Current", IF(Table2[[#This Row],[Days_Past_Due]]<=30,"1-30", IF(Table2[[#This Row],[Days_Past_Due]]<=60,"31-60", IF(Table2[[#This Row],[Days_Past_Due]]<=90,"61-90","90+")))) -> Current | N4: {=_xlfn.IFS(Table2[[#This Row],[DPD_Bucket]]="1-30","Overdue",Table2[[#This Row],[DPD_Bucket]]="90+","NPA",Table2[[#This Row],[DPD_Bucket]]="Current","Active",Table2[[#This Row],[DPD_Bucket]]="31-60","Overdue")} -> Active
A5: CUST0004 | B5: =_xlfn.XLOOKUP(Table2[[#This Row],[Customer_ID]],Table1[Customer_ID],Table1[Customer_Name],,0,) -> Mahesh Patel | C5: =_xlfn.XLOOKUP(Table2[[#This Row],[Customer_ID]],Table1[Customer_ID],Table1[Branch_Name],,) -> Gwalior | D5: =_xlfn.XLOOKUP(Table2[[#This Row],[Customer_ID]],Table1[Customer_ID],Table1[Vehicle_Make],,0) -> Hero | E5: =_xlfn.XLOOKUP(Table2[[#This Row],[Customer_ID]],Table1[Customer_ID],Table1[Vehicle_Model],,) -> Splendor | F5: =_xlfn.XLOOKUP(Table2[[#This Row],[Customer_ID]],Table1[Customer_ID],Table1[Amount_Disbursed],,) -> 35571 | G5: =_xlfn.XLOOKUP(Table2[[#This Row],[Customer_ID]],Table1[Customer_ID],Table1[EMI_Amount],,0) -> 960.64883 | H5: =Table2[[#This Row],[EMI_Amount]] -> 960.64883 | I5: 194 | J5: =Table2[[#This Row],[EMI_Due_May26]]-Table2[[#This Row],[Amount_Received_May26]] -> 766.64883 | K5: =DATE(2026,5,DAY(Table1[[#This Row],[Maturity_Date]])) -> 46165 | L5: =IF(Table2[[#This Row],[Overdue_Amount]]<1,"",MAX(0,TODAY()-Table2[[#This Row],[EMI_Due_Date]])) -> 15 | M5: =IF(LEN(Table2[[#This Row],[Days_Past_Due]])=0,"Current", IF(Table2[[#This Row],[Days_Past_Due]]<=30,"1-30", IF(Table2[[#This Row],[Days_Past_Due]]<=60,"31-60", IF(Table2[[#This Row],[Days_Past_Due]]<=90,"61-90","90+")))) -> 1-30 | N5: {=_xlfn.IFS(Table2[[#This Row],[DPD_Bucket]]="1-30","Overdue",Table2[[#This Row],[DPD_Bucket]]="90+","NPA",Table2[[#This Row],[DPD_Bucket]]="Current","Active",Table2[[#This Row],[DPD_Bucket]]="31-60","Overdue")} -> Overdue
A6: CUST0005 | B6: =_xlfn.XLOOKUP(Table2[[#This Row],[Customer_ID]],Table1[Customer_ID],Table1[Customer_Name],,0,) -> Santosh Mishra | C6: =_xlfn.XLOOKUP(Table2[[#This Row],[Customer_ID]],Table1[Customer_ID],Table1[Branch_Name],,) -> Rewa | D6: =_xlfn.XLOOKUP(Table2[[#This Row],[Customer_ID]],Table1[Customer_ID],Table1[Vehicle_Make],,0) -> Maruti | E6: =_xlfn.XLOOKUP(Table2[[#This Row],[Customer_ID]],Table1[Customer_ID],Table1[Vehicle_Model],,) -> Dzire | F6: =_xlfn.XLOOKUP(Table2[[#This Row],[Customer_ID]],Table1[Customer_ID],Table1[Amount_Disbursed],,) -> 494849 | G6: =_xlfn.XLOOKUP(Table2[[#This Row],[Customer_ID]],Table1[Customer_ID],Table1[EMI_Amount],,0) -> 43747.117 | H6: =Table2[[#This Row],[EMI_Amount]] -> 43747.117 | I6: 43747 | J6: =Table2[[#This Row],[EMI_Due_May26]]-Table2[[#This Row],[Amount_Received_May26]] -> 0.11732015 | K6: =DATE(2026,5,DAY(Table1[[#This Row],[Maturity_Date]])) -> 46159 | L6: =IF(Table2[[#This Row],[Overdue_Amount]]<1,"",MAX(0,TODAY()-Table2[[#This Row],[EMI_Due_Date]])) | M6: =IF(LEN(Table2[[#This Row],[Days_Past_Due]])=0,"Current", IF(Table2[[#This Row],[Days_Past_Due]]<=30,"1-30", IF(Table2[[#This Row],[Days_Past_Due]]<=60,"31-60", IF(Table2[[#This Row],[Days_Past_Due]]<=90,"61-90","90+")))) -> Current | N6: {=_xlfn.IFS(Table2[[#This Row],[DPD_Bucket]]="1-30","Overdue",Table2[[#This Row],[DPD_Bucket]]="90+","NPA",Table2[[#This Row],[DPD_Bucket]]="Current","Active",Table2[[#This Row],[DPD_Bucket]]="31-60","Overdue")} -> Active
A7: CUST0006 | B7: =_xlfn.XLOOKUP(Table2[[#This Row],[Customer_ID]],Table1[Customer_ID],Table1[Customer_Name],,0,) -> Deepak Malviya | C7: =_xlfn.XLOOKUP(Table2[[#This Row],[Customer_ID]],Table1[Customer_ID],Table1[Branch_Name],,) -> Jabalpur | D7: =_xlfn.XLOOKUP(Table2[[#This Row],[Customer_ID]],Table1[Customer_ID],Table1[Vehicle_Make],,0) -> Honda | E7: =_xlfn.XLOOKUP(Table2[[#This Row],[Customer_ID]],Table1[Customer_ID],Table1[Vehicle_Model],,) -> Activa | F7: =_xlfn.XLOOKUP(Table2[[#This Row],[Customer_ID]],Table1[Customer_ID],Table1[Amount_Disbursed],,) -> 38984 | G7: =_xlfn.XLOOKUP(Table2[[#This Row],[Customer_ID]],Table1[Customer_ID],Table1[EMI_Amount],,0) -> 1903.0086 | H7: =Table2[[#This Row],[EMI_Amount]] -> 1903.0086 | I7: 1903 | J7: =Table2[[#This Row],[EMI_Due_May26]]-Table2[[#This Row],[Amount_Received_May26]] -> 0.0086001553 | K7: =DATE(2026,5,DAY(Table1[[#This Row],[Maturity_Date]])) -> 46167 | L7: =IF(Table2[[#This Row],[Overdue_Amount]]<1,"",MAX(0,TODAY()-Table2[[#This Row],[EMI_Due_Date]])) | M7: =IF(LEN(Table2[[#This Row],[Days_Past_Due]])=0,"Current", IF(Table2[[#This Row],[Days_Past_Due]]<=30,"1-30", IF(Table2[[#This Row],[Days_Past_Due]]<=60,"31-60", IF(Table2[[#This Row],[Days_Past_Due]]<=90,"61-90","90+")))) -> Current | N7: {=_xlfn.IFS(Table2[[#This Row],[DPD_Bucket]]="1-30","Overdue",Table2[[#This Row],[DPD_Bucket]]="90+","NPA",Table2[[#This Row],[DPD_Bucket]]="Current","Active",Table2[[#This Row],[DPD_Bucket]]="31-60","Overdue")} -> Active
A8: CUST0008 | B8: =_xlfn.XLOOKUP(Table2[[#This Row],[Customer_ID]],Table1[Customer_ID],Table1[Customer_Name],,0,) -> Dinesh Sharma | C8: =_xlfn.XLOOKUP(Table2[[#This Row],[Customer_ID]],Table1[Customer_ID],Table1[Branch_Name],,) -> Bhopal | D8: =_xlfn.XLOOKUP(Table2[[#This Row],[Customer_ID]],Table1[Customer_ID],Table1[Vehicle_Make],,0) -> Honda | E8: =_xlfn.XLOOKUP(Table2[[#This Row],[Customer_ID]],Table1[Customer_ID],Table1[Vehicle_Model],,) -> City | F8: =_xlfn.XLOOKUP(Table2[[#This Row],[Customer_ID]],Table1[Customer_ID],Table1[Amount_Disbursed],,) -> 872459 | G8: =_xlfn.XLOOKUP(Table2[[#This Row],[Customer_ID]],Table1[Customer_ID],Table1[EMI_Amount],,0) -> 42659.968 | H8: =Table2[[#This Row],[EMI_Amount]] -> 42659.968 | I8: 0 | J8: =Table2[[#This Row],[EMI_Due_May26]]-Table2[[#This Row],[Amount_Received_May26]] -> 42659.968 | K8: =DATE(2026,5,DAY(Table1[[#This Row],[Maturity_Date]])) -> 46157 | L8: =IF(Table2[[#This Row],[Overdue_Amount]]<1,"",MAX(0,TODAY()-Table2[[#This Row],[EMI_Due_Date]])) -> 23 | M8: =IF(LEN(Table2[[#This Row],[Days_Past_Due]])=0,"Current", IF(Table2[[#This Row],[Days_Past_Due]]<=30,"1-30", IF(Table2[[#This Row],[Days_Past_Due]]<=60,"31-60", IF(Table2[[#This Row],[Days_Past_Due]]<=90,"61-90","90+")))) -> 1-30 | N8: {=_xlfn.IFS(Table2[[#This Row],[DPD_Bucket]]="1-30","Overdue",Table2[[#This Row],[DPD_Bucket]]="90+","NPA",Table2[[#This Row],[DPD_Bucket]]="Current","Active",Table2[[#This Row],[DPD_Bucket]]="31-60","Overdue")} -> Overdue
A9: CUST0009 | B9: =_xlfn.XLOOKUP(Table2[[#This Row],[Customer_ID]],Table1[Customer_ID],Table1[Customer_Name],,0,) -> Meena Gupta | C9: =_xlfn.XLOOKUP(Table2[[#This Row],[Customer_ID]],Table1[Customer_ID],Table1[Branch_Name],,) -> Bhopal | D9: =_xlfn.XLOOKUP(Table2[[#This Row],[Customer_ID]],Table1[Customer_ID],Table1[Vehicle_Make],,0) -> Honda | E9: =_xlfn.XLOOKUP(Table2[[#This Row],[Customer_ID]],Table1[Customer_ID],Table1[Vehicle_Model],,) -> City | F9: =_xlfn.XLOOKUP(Table2[[#This Row],[Customer_ID]],Table1[Customer_ID],Table1[Amount_Disbursed],,) -> 936007 | G9: =_xlfn.XLOOKUP(Table2[[#This Row],[Customer_ID]],Table1[Customer_ID],Table1[EMI_Amount],,0) -> 21653.284 | H9: =Table2[[#This Row],[EMI_Amount]] -> 21653.284 | I9: 5106 | J9: =Table2[[#This Row],[EMI_Due_May26]]-Table2[[#This Row],[Amount_Received_May26]] -> 16547.284 | K9: =DATE(2026,5,DAY(Table1[[#This Row],[Maturity_Date]])) -> 46159 | L9: =IF(Table2[[#This Row],[Overdue_Amount]]<1,"",MAX(0,TODAY()-Table2[[#This Row],[EMI_Due_Date]])) -> 21 | M9: =IF(LEN(Table2[[#This Row],[Days_Past_Due]])=0,"Current", IF(Table2[[#This Row],[Days_Past_Due]]<=30,"1-30", IF(Table2[[#This Row],[Days_Past_Due]]<=60,"31-60", IF(Table2[[#This Row],[Days_Past_Due]]<=90,"61-90","90+")))) -> 1-30 | N9: {=_xlfn.IFS(Table2[[#This Row],[DPD_Bucket]]="1-30","Overdue",Table2[[#This Row],[DPD_Bucket]]="90+","NPA",Table2[[#This Row],[DPD_Bucket]]="Current","Active",Table2[[#This Row],[DPD_Bucket]]="31-60","Overdue")} -> Overdue
A10: CUST0011 | B10: =_xlfn.XLOOKUP(Table2[[#This Row],[Customer_ID]],Table1[Customer_ID],Table1[Customer_Name],,0,) -> Naresh Dwivedi | C10: =_xlfn.XLOOKUP(Table2[[#This Row],[Customer_ID]],Table1[Customer_ID],Table1[Branch_Name],,) -> Bhopal | D10: =_xlfn.XLOOKUP(Table2[[#This Row],[Customer_ID]],Table1[Customer_ID],Table1[Vehicle_Make],,0) -> Honda | E10: =_xlfn.XLOOKUP(Table2[[#This Row],[Customer_ID]],Table1[Customer_ID],Table1[Vehicle_Model],,) -> City | F10: =_xlfn.XLOOKUP(Table2[[#This Row],[Customer_ID]],Table1[Customer_ID],Table1[Amount_Disbursed],,) -> 874852 | G10: =_xlfn.XLOOKUP(Table2[[#This Row],[Customer_ID]],Table1[Customer_ID],Table1[EMI_Amount],,0) -> 41010.94 | H10: =Table2[[#This Row],[EMI_Amount]] -> 41010.94 | I10: 25092 | J10: =Table2[[#This Row],[EMI_Due_May26]]-Table2[[#This Row],[Amount_Received_May26]] -> 15918.94 | K10: =DATE(2026,5,DAY(Table1[[#This Row],[Maturity_Date]])) -> 46171 | L10: =IF(Table2[[#This Row],[Overdue_Amount]]<1,"",MAX(0,TODAY()-Table2[[#This Row],[EMI_Due_Date]])) -> 9 | M10: =IF(LEN(Table2[[#This Row],[Days_Past_Due]])=0,"Current", IF(Table2[[#This Row],[Days_Past_Due]]<=30,"1-30", IF(Table2[[#This Row],[Days_Past_Due]]<=60,"31-60", IF(Table2[[#This Row],[Days_Past_Due]]<=90,"61-90","90+")))) -> 1-30 | N10: {=_xlfn.IFS(Table2[[#This Row],[DPD_Bucket]]="1-30","Overdue",Table2[[#This Row],[DPD_Bucket]]="90+","NPA",Table2[[#This Row],[DPD_Bucket]]="Current","Active",Table2[[#This Row],[DPD_Bucket]]="31-60","Overdue")} -> Overdue | LW10: 90+
A11: CUST0012 | B11: =_xlfn.XLOOKUP(Table2[[#This Row],[Customer_ID]],Table1[Customer_ID],Table1[Customer_Name],,0,) -> Asha Singh | C11: =_xlfn.XLOOKUP(Table2[[#This Row],[Customer_ID]],Table1[Customer_ID],Table1[Branch_Name],,) -> Indore | D11: =_xlfn.XLOOKUP(Table2[[#This Row],[Customer_ID]],Table1[Customer_ID],Table1[Vehicle_Make],,0) -> Hyundai | E11: =_xlfn.XLOOKUP(Table2[[#This Row],[Customer_ID]],Table1[Customer_ID],Table1[Vehicle_Model],,) -> i20 | F11: =_xlfn.XLOOKUP(Table2[[#This Row],[Customer_ID]],Table1[Customer_ID],Table1[Amount_Disbursed],,) -> 599235 | G11: =_xlfn.XLOOKUP(Table2[[#This Row],[Customer_ID]],Table1[Customer_ID],Table1[EMI_Amount],,0) -> 29120.422 | H11: =Table2[[#This Row],[EMI_Amount]] -> 29120.422 | I11: 29120 | J11: =Table2[[#This Row],[EMI_Due_May26]]-Table2[[#This Row],[Amount_Received_May26]] -> 0.42152583 | K11: =DATE(2026,5,DAY(Table1[[#This Row],[Maturity_Date]])) -> 46152 | L11: =IF(Table2[[#This Row],[Overdue_Amount]]<1,"",MAX(0,TODAY()-Table2[[#This Row],[EMI_Due_Date]])) | M11: =IF(LEN(Table2[[#This Row],[Days_Past_Due]])=0,"Current", IF(Table2[[#This Row],[Days_Past_Due]]<=30,"1-30", IF(Table2[[#This Row],[Days_Past_Due]]<=60,"31-60", IF(Table2[[#This Row],[Days_Past_Due]]<=90,"61-90","90+")))) -> Current | N11: {=_xlfn.IFS(Table2[[#This Row],[DPD_Bucket]]="1-30","Overdue",Table2[[#This Row],[DPD_Bucket]]="90+","NPA",Table2[[#This Row],[DPD_Bucket]]="Current","Active",Table2[[#This Row],[DPD_Bucket]]="31-60","Overdue")} -> Active
A12: CUST0013 | B12: =_xlfn.XLOOKUP(Table2[[#This Row],[Customer_ID]],Table1[Customer_ID],Table1[Customer_Name],,0,) -> Ramesh Verma | C12: =_xlfn.XLOOKUP(Table2[[#This Row],[Customer_ID]],Table1[Customer_ID],Table1[Branch_Name],,) -> Jabalpur | D12: =_xlfn.XLOOKUP(Table2[[#This Row],[Customer_ID]],Table1[Customer_ID],Table1[Vehicle_Make],,0) -> Maruti | E12: =_xlfn.XLOOKUP(Table2[[#This Row],[Customer_ID]],Table1[Customer_ID],Table1[Vehicle_Model],,) -> Swift | F12: =_xlfn.XLOOKUP(Table2[[#This Row],[Customer_ID]],Table1[Customer_ID],Table1[Amount_Disbursed],,) -> 538554 | G12: =_xlfn.XLOOKUP(Table2[[#This Row],[Customer_ID]],Table1[Customer_ID],Table1[EMI_Amount],,0) -> 33246.325 | H12: =Table2[[#This Row],[EMI_Amount]] -> 33246.325 | I12: 33246 | J12: =Table2[[#This Row],[EMI_Due_May26]]-Table2[[#This Row],[Amount_Received_May26]] -> 0.325458 | K12: =DATE(2026,5,DAY(Table1[[#This Row],[Maturity_Date]])) -> 46159 | L12: =IF(Table2[[#This Row],[Overdue_Amount]]<1,"",MAX(0,TODAY()-Table2[[#This Row],[EMI_Due_Date]])) | M12: =IF(LEN(Table2[[#This Row],[Days_Past_Due]])=0,"Current", IF(Table2[[#This Row],[Days_Past_Due]]<=30,"1-30", IF(Table2[[#This Row],[Days_Past_Due]]<=60,"31-60", IF(Table2[[#This Row],[Days_Past_Due]]<=90,"61-90","90+")))) -> Current | N12: {=_xlfn.IFS(Table2[[#This Row],[DPD_Bucket]]="1-30","Overdue",Table2[[#This Row],[DPD_Bucket]]="90+","NPA",Table2[[#This Row],[DPD_Bucket]]="Current","Active",Table2[[#This Row],[DPD_Bucket]]="31-60","Overdue")} -> Active
A13: CUST0014 | B13: =_xlfn.XLOOKUP(Table2[[#This Row],[Customer_ID]],Table1[Customer_ID],Table1[Customer_Name],,0,) -> Ajay Chauhan | C13: =_xlfn.XLOOKUP(Table2[[#This Row],[Customer_ID]],Table1[Customer_ID],Table1[Branch_Name],,) -> Rewa | D13: =_xlfn.XLOOKUP(Table2[[#This Row],[Customer_ID]],Table1[Customer_ID],Table1[Vehicle_Make],,0) -> Honda | E13: =_xlfn.XLOOKUP(Table2[[#This Row],[Customer_ID]],Table1[Customer_ID],Table1[Vehicle_Model],,) -> City | F13: =_xlfn.XLOOKUP(Table2[[#This Row],[Customer_ID]],Table1[Customer_ID],Table1[Amount_Disbursed],,) -> 866248 | G13: =_xlfn.XLOOKUP(Table2[[#This Row],[Customer_ID]],Table1[Customer_ID],Table1[EMI_Amount],,0) -> 19860.902 | H13: =Table2[[#This Row],[EMI_Amount]] -> 19860.902 | I13: 19861 | J13: =Table2[[#This Row],[EMI_Due_May26]]-Table2[[#This Row],[Amount_Received_May26]] -> -0.098274357 | K13: =DATE(2026,5,DAY(Table1[[#This Row],[Maturity_Date]])) -> 46161 | L13: =IF(Table2[[#This Row],[Overdue_Amount]]<1,"",MAX(0,TODAY()-Table2[[#This Row],[EMI_Due_Date]])) | M13: =IF(LEN(Table2[[#This Row],[Days_Past_Due]])=0,"Current", IF(Table2[[#This Row],[Days_Past_Due]]<=30,"1-30", IF(Table2[[#This Row],[Days_Past_Due]]<=60,"31-60", IF(Table2[[#This Row],[Days_Past_Due]]<=90,"61-90","90+")))) -> Current | N13: {=_xlfn.IFS(Table2[[#This Row],[DPD_Bucket]]="1-30","Overdue",Table2[[#This Row],[DPD_Bucket]]="90+","NPA",Table2[[#This Row],[DPD_Bucket]]="Current","Active",Table2[[#This Row],[DPD_Bucket]]="31-60","Overdue")} -> Active
A14: CUST0015 | B14: =_xlfn.XLOOKUP(Table2[[#This Row],[Customer_ID]],Table1[Customer_ID],Table1[Customer_Name],,0,) -> Seema Joshi | C14: =_xlfn.XLOOKUP(Table2[[#This Row],[Customer_ID]],Table1[Customer_ID],Table1[Branch_Name],,) -> Bhopal | D14: =_xlfn.XLOOKUP(Table2[[#This Row],[Customer_ID]],Table1[Customer_ID],Table1[Vehicle_Make],,0) -> Renault | E14: =_xlfn.XLOOKUP(Table2[[#This Row],[Customer_ID]],Table1[Customer_ID],Table1[Vehicle_Model],,) -> Kwid | F14: =_xlfn.XLOOKUP(Table2[[#This Row],[Customer_ID]],Table1[Customer_ID],Table1[Amount_Disbursed],,) -> 363463 | G14: =_xlfn.XLOOKUP(Table2[[#This Row],[Customer_ID]],Table1[Customer_ID],Table1[EMI_Amount],,0) -> 7823.045 | H14: =Table2[[#This Row],[EMI_Amount]] -> 7823.045 | I14: 5486 | J14: =Table2[[#This Row],[EMI_Due_May26]]-Table2[[#This Row],[Amount_Received_May26]] -> 2337.045 | K14: =DATE(2026,5,DAY(Table1[[#This Row],[Maturity_Date]])) -> 46152 | L14: =IF(Table2[[#This Row],[Overdue_Amount]]<1,"",MAX(0,TODAY()-Table2[[#This Row],[EMI_Due_Date]])) -> 28 | M14: =IF(LEN(Table2[[#This Row],[Days_Past_Due]])=0,"Current", IF(Table2[[#This Row],[Days_Past_Due]]<=30,"1-30", IF(Table2[[#This Row],[Days_Past_Due]]<=60,"31-60", IF(Table2[[#This Row],[Days_Past_Due]]<=90,"61-90","90+")))) -> 1-30 | N14: {=_xlfn.IFS(Table2[[#This Row],[DPD_Bucket]]="1-30","Overdue",Table2[[#This Row],[DPD_Bucket]]="90+","NPA",Table2[[#This Row],[DPD_Bucket]]="Current","Active",Table2[[#This Row],[DPD_Bucket]]="31-60","Overdue")} -> Overdue
A15: CUST0016 | B15: =_xlfn.XLOOKUP(Table2[[#This Row],[Customer_ID]],Table1[Customer_ID],Table1[Customer_Name],,0,) -> Asha Jain | C15: =_xlfn.XLOOKUP(Table2[[#This Row],[Customer_ID]],Table1[Customer_ID],Table1[Branch_Name],,) -> Jabalpur | D15: =_xlfn.XLOOKUP(Table2[[#This Row],[Customer_ID]],Table1[Customer_ID],Table1[Vehicle_Make],,0) -> Hero | E15: =_xlfn.XLOOKUP(Table2[[#This Row],[Customer_ID]],Table1[Customer_ID],Table1[Vehicle_Model],,) -> Splendor | F15: =_xlfn.XLOOKUP(Table2[[#This Row],[Customer_ID]],Table1[Customer_ID],Table1[Amount_Disbursed],,) -> 55853 | G15: =_xlfn.XLOOKUP(Table2[[#This Row],[Customer_ID]],Table1[Customer_ID],Table1[EMI_Amount],,0) -> 2707.5941 | H15: =Table2[[#This Row],[EMI_Amount]] -> 2707.5941 | I15: 2708 | J15: =Table2[[#This Row],[EMI_Due_May26]]-Table2[[#This Row],[Amount_Received_May26]] -> -0.40594813 | K15: =DATE(2026,5,DAY(Table1[[#This Row],[Maturity_Date]])) -> 46166 | L15: =IF(Table2[[#This Row],[Overdue_Amount]]<1,"",MAX(0,TODAY()-Table2[[#This Row],[EMI_Due_Date]])) | M15: =IF(LEN(Table2[[#This Row],[Days_Past_Due]])=0,"Current", IF(Table2[[#This Row],[Days_Past_Due]]<=30,"1-30", IF(Table2[[#This Row],[Days_Past_Due]]<=60,"31-60", IF(Table2[[#This Row],[Days_Past_Due]]<=90,"61-90","90+")))) -> Current | N15: {=_xlfn.IFS(Table2[[#This Row],[DPD_Bucket]]="1-30","Overdue",Table2[[#This Row],[DPD_Bucket]]="90+","NPA",Table2[[#This Row],[DPD_Bucket]]="Current","Active",Table2[[#This Row],[DPD_Bucket]]="31-60","Overdue")} -> Active
A16: CUST0017 | B16: =_xlfn.XLOOKUP(Table2[[#This Row],[Customer_ID]],Table1[Customer_ID],Table1[Customer_Name],,0,) -> Lata Gupta | C16: =_xlfn.XLOOKUP(Table2[[#This Row],[Customer_ID]],Table1[Customer_ID],Table1[Branch_Name],,) -> Gwalior | D16: =_xlfn.XLOOKUP(Table2[[#This Row],[Customer_ID]],Table1[Customer_ID],Table1[Vehicle_Make],,0) -> TVS | E16: =_xlfn.XLOOKUP(Table2[[#This Row],[Customer_ID]],Table1[Customer_ID],Table1[Vehicle_Model],,) -> Jupiter | F16: =_xlfn.XLOOKUP(Table2[[#This Row],[Customer_ID]],Table1[Customer_ID],Table1[Amount_Disbursed],,) -> 64394 | G16: =_xlfn.XLOOKUP(Table2[[#This Row],[Customer_ID]],Table1[Customer_ID],Table1[EMI_Amount],,0) -> 1453.6499 | H16: =Table2[[#This Row],[EMI_Amount]] -> 1453.6499 | I16: 1048 | J16: =Table2[[#This Row],[EMI_Due_May26]]-Table2[[#This Row],[Amount_Received_May26]] -> 405.64988 | K16: =DATE(2026,5,DAY(Table1[[#This Row],[Maturity_Date]])) -> 46168 | L16: =IF(Table2[[#This Row],[Overdue_Amount]]<1,"",MAX(0,TODAY()-Table2[[#This Row],[EMI_Due_Date]])) -> 12 | M16: =IF(LEN(Table2[[#This Row],[Days_Past_Due]])=0,"Current", IF(Table2[[#This Row],[Days_Past_Due]]<=30,"1-30", IF(Table2[[#This Row],[Days_Past_Due]]<=60,"31-60", IF(Table2[[#This Row],[Days_Past_Due]]<=90,"61-90","90+")))) -> 1-30 | N16: {=_xlfn.IFS(Table2[[#This Row],[DPD_Bucket]]="1-30","Overdue",Table2[[#This Row],[DPD_Bucket]]="90+","NPA",Table2[[#This Row],[DPD_Bucket]]="Current","Active",Table2[[#This Row],[DPD_Bucket]]="31-60","Overdue")} -> Overdue
A17: CUST0018 | B17: =_xlfn.XLOOKUP(Table2[[#This Row],[Customer_ID]],Table1[Customer_ID],Table1[Customer_Name],,0,) -> Kiran Sharma | C17: =_xlfn.XLOOKUP(Table2[[#This Row],[Customer_ID]],Table1[Customer_ID],Table1[Branch_Name],,) -> Bhopal | D17: =_xlfn.XLOOKUP(Table2[[#This Row],[Customer_ID]],Table1[Customer_ID],Table1[Vehicle_Make],,0) -> Bajaj | E17: =_xlfn.XLOOKUP(Table2[[#This Row],[Customer_ID]],Table1[Customer_ID],Table1[Vehicle_Model],,) -> Pulsar | F17: =_xlfn.XLOOKUP(Table2[[#This Row],[Customer_ID]],Table1[Customer_ID],Table1[Amount_Disbursed],,) -> 77753 | G17: =_xlfn.XLOOKUP(Table2[[#This Row],[Customer_ID]],Table1[Customer_ID],Table1[EMI_Amount],,0) -> 2686.5841 | H17: =Table2[[#This Row],[EMI_Amount]] -> 2686.5841 | I17: 2687 | J17: =Table2[[#This Row],[EMI_Due_May26]]-Table2[[#This Row],[Amount_Received_May26]] -> -0.41594581 | K17: =DATE(2026,5,DAY(Table1[[#This Row],[Maturity_Date]])) -> 46169 | L17: =IF(Table2[[#This Row],[Overdue_Amount]]<1,"",MAX(0,TODAY()-Table2[[#This Row],[EMI_Due_Date]])) | M17: =IF(LEN(Table2[[#This Row],[Days_Past_Due]])=0,"Current", IF(Table2[[#This Row],[Days_Past_Due]]<=30,"1-30", IF(Table2[[#This Row],[Days_Past_Due]]<=60,"31-60", IF(Table2[[#This Row],[Days_Past_Due]]<=90,"61-90","90+")))) -> Current | N17: {=_xlfn.IFS(Table2[[#This Row],[DPD_Bucket]]="1-30","Overdue",Table2[[#This Row],[DPD_Bucket]]="90+","NPA",Table2[[#This Row],[DPD_Bucket]]="Current","Active",Table2[[#This Row],[DPD_Bucket]]="31-60","Overdue")} -> Active
A18: CUST0020 | B18: =_xlfn.XLOOKUP(Table2[[#This Row],[Customer_ID]],Table1[Customer_ID],Table1[Customer_Name],,0,) -> Kiran Dwivedi | C18: =_xlfn.XLOOKUP(Table2[[#This Row],[Customer_ID]],Table1[Customer_ID],Table1[Branch_Name],,) -> Gwalior | D18: =_xlfn.XLOOKUP(Table2[[#This Row],[Customer_ID]],Table1[Customer_ID],Table1[Vehicle_Make],,0) -> Honda | E18: =_xlfn.XLOOKUP(Table2[[#This Row],[Customer_ID]],Table1[Customer_ID],Table1[Vehicle_Model],,) -> City | F18: =_xlfn.XLOOKUP(Table2[[#This Row],[Customer_ID]],Table1[Customer_ID],Table1[Amount_Disbursed],,) -> 905436 | G18: =_xlfn.XLOOKUP(Table2[[#This Row],[Customer_ID]],Table1[Customer_ID],Table1[EMI_Amount],,0) -> 79834.006 | H18: =Table2[[#This Row],[EMI_Amount]] -> 79834.006 | I18: 79834 | J18: =Table2[[#This Row],[EMI_Due_May26]]-Table2[[#This Row],[Amount_Received_May26]] -> 0.0062576602 | K18: =DATE(2026,5,DAY(Table1[[#This Row],[Maturity_Date]])) -> 46173 | L18: =IF(Table2[[#This Row],[Overdue_Amount]]<1,"",MAX(0,TODAY()-Table2[[#This Row],[EMI_Due_Date]])) | M18: =IF(LEN(Table2[[#This Row],[Days_Past_Due]])=0,"Current", IF(Table2[[#This Row],[Days_Past_Due]]<=30,"1-30", IF(Table2[[#This Row],[Days_Past_Due]]<=60,"31-60", IF(Table2[[#This Row],[Days_Past_Due]]<=90,"61-90","90+")))) -> Current | N18: {=_xlfn.IFS(Table2[[#This Row],[DPD_Bucket]]="1-30","Overdue",Table2[[#This Row],[DPD_Bucket]]="90+","NPA",Table2[[#This Row],[DPD_Bucket]]="Current","Active",Table2[[#This Row],[DPD_Bucket]]="31-60","Overdue")} -> Active
A19: CUST0021 | B19: =_xlfn.XLOOKUP(Table2[[#This Row],[Customer_ID]],Table1[Customer_ID],Table1[Customer_Name],,0,) -> Renu Soni | C19: =_xlfn.XLOOKUP(Table2[[#This Row],[Customer_ID]],Table1[Customer_ID],Table1[Branch_Name],,) -> Bhopal | D19: =_xlfn.XLOOKUP(Table2[[#This Row],[Customer_ID]],Table1[Customer_ID],Table1[Vehicle_Make],,0) -> Maruti | E19: =_xlfn.XLOOKUP(Table2[[#This Row],[Customer_ID]],Table1[Customer_ID],Table1[Vehicle_Model],,) -> Dzire | F19: =_xlfn.XLOOKUP(Table2[[#This Row],[Customer_ID]],Table1[Customer_ID],Table1[Amount_Disbursed],,) -> 591412 | G19: =_xlfn.XLOOKUP(Table2[[#This Row],[Customer_ID]],Table1[Customer_ID],Table1[EMI_Amount],,0) -> 16268.21 | H19: =Table2[[#This Row],[EMI_Amount]] -> 16268.21 | I19: 16268 | J19: =Table2[[#This Row],[EMI_Due_May26]]-Table2[[#This Row],[Amount_Received_May26]] -> 0.21020272 | K19: =DATE(2026,5,DAY(Table1[[#This Row],[Maturity_Date]])) -> 46165 | L19: =IF(Table2[[#This Row],[Overdue_Amount]]<1,"",MAX(0,TODAY()-Table2[[#This Row],[EMI_Due_Date]])) | M19: =IF(LEN(Table2[[#This Row],[Days_Past_Due]])=0,"Current", IF(Table2[[#This Row],[Days_Past_Due]]<=30,"1-30", IF(Table2[[#This Row],[Days_Past_Due]]<=60,"31-60", IF(Table2[[#This Row],[Days_Past_Due]]<=90,"61-90","90+")))) -> Current | N19: {=_xlfn.IFS(Table2[[#This Row],[DPD_Bucket]]="1-30","Overdue",Table2[[#This Row],[DPD_Bucket]]="90+","NPA",Table2[[#This Row],[DPD_Bucket]]="Current","Active",Table2[[#This Row],[DPD_Bucket]]="31-60","Overdue")} -> Active
A20: CUST0022 | B20: =_xlfn.XLOOKUP(Table2[[#This Row],[Customer_ID]],Table1[Customer_ID],Table1[Customer_Name],,0,) -> Pradeep Pandey | C20: =_xlfn.XLOOKUP(Table2[[#This Row],[Customer_ID]],Table1[Customer_ID],Table1[Branch_Name],,) -> Gwalior | D20: =_xlfn.XLOOKUP(Table2[[#This Row],[Customer_ID]],Table1[Customer_ID],Table1[Vehicle_Make],,0) -> Tata | E20: =_xlfn.XLOOKUP(Table2[[#This Row],[Customer_ID]],Table1[Customer_ID],Table1[Vehicle_Model],,) -> Nexon | F20: =_xlfn.XLOOKUP(Table2[[#This Row],[Customer_ID]],Table1[Customer_ID],Table1[Amount_Disbursed],,) -> 737287 | G20: =_xlfn.XLOOKUP(Table2[[#This Row],[Customer_ID]],Table1[Customer_ID],Table1[EMI_Amount],,0) -> 16159.398 | H20: =Table2[[#This Row],[EMI_Amount]] -> 16159.398 | I20: 16159 | J20: =Table2[[#This Row],[EMI_Due_May26]]-Table2[[#This Row],[Amount_Received_May26]] -> 0.39783303 | K20: =DATE(2026,5,DAY(Table1[[#This Row],[Maturity_Date]])) -> 46159 | L20: =IF(Table2[[#This Row],[Overdue_Amount]]<1,"",MAX(0,TODAY()-Table2[[#This Row],[EMI_Due_Date]])) | M20: =IF(LEN(Table2[[#This Row],[Days_Past_Due]])=0,"Current", IF(Table2[[#This Row],[Days_Past_Due]]<=30,"1-30", IF(Table2[[#This Row],[Days_Past_Due]]<=60,"31-60", IF(Table2[[#This Row],[Days_Past_Due]]<=90,"61-90","90+")))) -> Current | N20: {=_xlfn.IFS(Table2[[#This Row],[DPD_Bucket]]="1-30","Overdue",Table2[[#This Row],[DPD_Bucket]]="90+","NPA",Table2[[#This Row],[DPD_Bucket]]="Current","Active",Table2[[#This Row],[DPD_Bucket]]="31-60","Overdue")} -> Active
